File: Essais_rupture/EXL120/corde5_2kN.csv
Méthode d'essai	traction.msm
Nom du lot	corde5_exl120.mss
Eprouvette n°	1

Force (N)	Temps (s)	Allongement (mm)	Contrainte (MPa)	Déformation (mm/mm)	Extensometer (mm)	Traverse (mm)

44.219	0.800	40.960	85.813	1.638	40.960	0.010
44.779	0.900	40.960	86.899	1.638	40.960	0.020
45.279	1.000	40.960	87.870	1.638	40.960	0.030
45.827	1.100	40.960	88.932	1.638	40.960	0.040
46.406	1.200	40.960	90.055	1.638	40.960	0.050
46.919	1.300	40.960	91.052	1.638	40.960	0.061
47.459	1.400	40.960	92.100	1.638	40.960	0.071
47.987	1.500	40.960	93.124	1.638	40.960	0.080
48.559	1.600	40.960	94.235	1.638	40.960	0.091
49.037	1.700	40.960	95.162	1.638	40.960	0.100
49.597	1.800	40.960	96.248	1.638	40.960	0.111
50.119	1.900	40.960	97.262	1.638	40.960	0.121
50.629	2.000	40.960	98.252	1.638	40.960	0.130
51.199	2.100	40.960	99.358	1.638	40.960	0.141
51.725	2.200	40.960	100.379	1.638	40.960	0.150
52.179	2.300	40.960	101.260	1.638	40.960	0.159
52.799	2.400	40.960	102.463	1.638	40.960	0.171
53.334	2.500	40.960	103.501	1.638	40.960	0.180
53.879	2.600	40.960	104.559	1.638	40.960	0.191
54.399	2.700	40.960	105.568	1.638	40.960	0.200
54.939	2.800	40.960	106.616	1.638	40.960	0.210
55.459	2.900	40.960	107.625	1.638	40.960	0.220
55.979	3.000	40.960	108.634	1.638	40.960	0.230
56.567	3.100	40.960	109.774	1.638	40.960	0.240
57.079	3.200	40.960	110.769	1.638	40.960	0.250
57.579	3.300	40.960	111.739	1.638	40.960	0.260
58.199	3.400	40.960	112.942	1.638	40.960	0.271
58.704	3.500	40.960	113.922	1.638	40.960	0.281
59.259	3.600	40.960	114.999	1.638	40.960	0.291
59.765	3.700	40.960	115.982	1.638	40.960	0.300
60.199	3.800	40.960	116.823	1.638	40.960	0.309
60.819	3.900	40.960	118.027	1.638	40.960	0.321
61.282	4.000	40.960	118.924	1.638	40.960	0.330
61.859	4.100	40.960	120.045	1.638	40.960	0.341
62.332	4.200	40.960	120.962	1.638	40.960	0.350
62.808	4.300	40.960	121.886	1.638	40.960	0.360
63.419	4.400	40.960	123.072	1.638	40.960	0.371
63.896	4.500	40.960	123.999	1.638	40.960	0.381
64.399	4.600	40.960	124.974	1.638	40.960	0.391
64.834	4.700	40.960	125.818	1.638	40.960	0.400
65.311	4.800	40.960	126.745	1.638	40.960	0.410
65.819	4.900	40.960	127.729	1.638	40.960	0.421
66.264	5.000	40.960	128.593	1.638	40.960	0.431
66.739	5.100	40.960	129.515	1.638	40.960	0.441
67.123	5.200	40.960	130.259	1.638	40.960	0.450
67.551	5.300	40.960	131.092	1.638	40.960	0.460
67.999	5.400	40.960	131.960	1.638	40.960	0.470
68.419	5.500	40.960	132.775	1.638	40.960	0.480
68.861	5.600	40.960	133.634	1.638	40.960	0.491
69.199	5.700	40.960	134.289	1.638	40.960	0.500
69.619	5.800	40.960	135.104	1.638	40.960	0.510
69.969	5.900	40.960	135.783	1.638	40.960	0.520
70.384	6.000	40.960	136.588	1.638	40.960	0.531
70.719	6.100	40.960	137.238	1.638	40.960	0.541
71.045	6.200	40.960	137.871	1.638	40.960	0.550
71.371	6.300	40.960	138.505	1.638	40.960	0.560
71.739	6.400	40.960	139.218	1.638	40.960	0.571
72.024	6.500	40.960	139.771	1.638	40.960	0.580
72.359	6.600	40.960	140.421	1.638	40.960	0.591
72.648	6.700	40.960	140.981	1.638	40.960	0.600
72.919	6.800	40.960	141.508	1.638	40.960	0.610
73.209	6.900	40.960	142.070	1.638	40.960	0.620
73.479	7.000	40.960	142.594	1.638	40.960	0.630
73.783	7.100	40.960	143.184	1.638	40.960	0.640
74.128	7.200	40.960	143.853	1.638	40.960	0.650
74.419	7.300	40.960	144.419	1.638	40.960	0.660
74.739	7.400	40.960	145.039	1.638	40.960	0.671
74.996	7.500	40.960	145.539	1.638	40.960	0.680
75.339	7.600	40.960	146.204	1.638	40.960	0.691
75.608	7.700	40.960	146.725	1.638	40.960	0.700
75.875	7.800	40.960	147.244	1.638	40.960	0.710
76.219	7.900	40.960	147.912	1.638	40.960	0.721
76.431	8.000	40.960	148.324	1.638	40.960	0.730
76.763	8.100	40.960	148.967	1.638	40.960	0.740
77.048	8.200	40.960	149.520	1.638	40.960	0.750
77.339	8.300	40.960	150.085	1.638	40.960	0.760
77.669	8.400	40.960	150.725	1.638	40.960	0.770
77.959	8.500	40.960	151.288	1.638	40.960	0.780
78.301	8.600	40.960	151.953	1.638	40.960	0.791
78.565	8.700	40.960	152.465	1.638	40.960	0.800
78.875	8.800	40.960	153.066	1.638	40.960	0.810
79.239	8.900	40.960	153.772	1.638	40.960	0.821
79.516	9.000	40.960	154.311	1.638	40.960	0.830
79.879	9.100	40.960	155.014	1.638	40.960	0.841
80.154	9.200	40.960	155.548	1.638	40.960	0.850
80.455	9.300	40.960	156.132	1.638	40.960	0.860
80.779	9.400	40.960	156.761	1.638	40.960	0.870
81.104	9.500	40.960	157.391	1.638	40.960	0.881
81.439	9.600	40.960	158.041	1.638	40.960	0.891
81.736	9.700	40.960	158.619	1.638	40.960	0.900
81.979	9.800	40.960	159.089	1.638	40.960	0.909
82.399	9.900	40.960	159.904	1.638	40.960	0.921
82.624	10.000	40.960	160.341	1.638	40.960	0.930
82.961	10.100	40.960	160.996	1.638	40.960	0.941
83.219	10.200	40.960	161.496	1.638	40.960	0.950
83.539	10.300	40.960	162.117	1.638	40.960	0.960
83.839	10.400	40.960	162.699	1.638	40.960	0.970
84.139	10.500	40.960	163.281	1.638	40.960	0.980
84.444	10.600	40.960	163.873	1.638	40.960	0.990
84.699	10.700	40.960	164.368	1.638	40.960	1.000
85.007	10.800	40.960	164.967	1.638	40.960	1.010
85.359	10.900	40.960	165.649	1.638	40.960	1.021
85.624	11.000	40.960	166.163	1.638	40.960	1.031
85.899	11.100	40.960	166.696	1.638	40.960	1.041
86.156	11.200	40.960	167.196	1.638	40.960	1.050
86.435	11.300	40.960	167.737	1.638	40.960	1.060
86.689	11.400	40.960	168.230	1.638	40.960	1.070
86.999	11.500	40.960	168.831	1.638	40.960	1.080
87.320	11.600	40.960	169.455	1.638	40.960	1.091
87.579	11.700	40.960	169.957	1.638	40.960	1.100
87.859	11.800	40.960	170.500	1.638	40.960	1.110
88.169	11.900	40.960	171.102	1.638	40.960	1.120
88.539	12.000	40.960	171.820	1.638	40.960	1.130
88.839	12.100	40.960	172.402	1.638	40.960	1.141
89.165	12.200	40.960	173.035	1.638	40.960	1.150
89.435	12.300	40.960	173.559	1.638	40.960	1.160
89.759	12.400	40.960	174.187	1.638	40.960	1.171
90.024	12.500	40.960	174.701	1.638	40.960	1.181
90.319	12.600	40.960	175.274	1.638	40.960	1.191
90.596	12.700	40.960	175.812	1.638	40.960	1.200
90.879	12.800	40.960	176.361	1.638	40.960	1.210
91.199	12.900	40.960	176.982	1.638	40.960	1.220
91.479	13.000	40.960	177.525	1.638	40.960	1.230
91.781	13.100	40.960	178.112	1.638	40.960	1.241
92.019	13.200	40.960	178.573	1.638	40.960	1.250
92.319	13.300	40.960	179.155	1.638	40.960	1.260
92.619	13.400	40.960	179.737	1.638	40.960	1.271
92.896	13.500	40.960	180.276	1.638	40.960	1.280
93.219	13.600	40.960	180.902	1.638	40.960	1.291
93.416	13.700	40.960	181.285	1.638	40.960	1.300
93.655	13.800	40.960	181.748	1.638	40.960	1.310
93.979	13.900	40.960	182.376	1.638	40.960	1.321
94.251	14.000	40.960	182.905	1.638	40.960	1.331
94.581	14.100	40.960	183.546	1.638	40.960	1.341
94.876	14.200	40.960	184.118	1.638	40.960	1.350
95.158	14.300	40.960	184.666	1.638	40.960	1.360
95.448	14.400	40.960	185.229	1.638	40.960	1.370
95.758	14.500	40.960	185.831	1.638	40.960	1.380
96.061	14.600	40.960	186.418	1.638	40.960	1.391
96.347	14.700	40.960	186.973	1.638	40.960	1.400
96.631	14.800	40.960	187.524	1.638	40.960	1.410
96.918	14.900	40.960	188.082	1.638	40.960	1.421
97.156	15.000	40.960	188.543	1.638	40.960	1.430
97.458	15.100	40.960	189.130	1.638	40.960	1.441
97.705	15.200	40.960	189.608	1.638	40.960	1.450
98.011	15.300	40.960	190.202	1.638	40.960	1.460
98.283	15.400	40.960	190.731	1.638	40.960	1.470
98.558	15.500	40.960	191.264	1.638	40.960	1.480
98.882	15.600	40.960	191.893	1.638	40.960	1.490
99.176	15.700	40.960	192.463	1.638	40.960	1.500
99.438	15.800	40.960	192.972	1.638	40.960	1.510
99.783	15.900	40.960	193.641	1.638	40.960	1.520
100.098	16.000	40.960	194.253	1.638	40.960	1.530
100.441	16.100	40.960	194.917	1.638	40.960	1.541
100.718	16.200	40.960	195.456	1.638	40.960	1.550
101.011	16.300	40.960	196.024	1.638	40.960	1.560
101.258	16.400	40.960	196.504	1.638	40.960	1.570
101.638	16.500	40.960	197.241	1.638	40.960	1.580
101.941	16.600	40.960	197.828	1.638	40.960	1.591
102.238	16.700	40.960	198.406	1.638	40.960	1.600
102.498	16.800	40.960	198.910	1.638	40.960	1.609
102.858	16.900	40.960	199.609	1.638	40.960	1.621
103.136	17.000	40.960	200.147	1.638	40.960	1.630
103.458	17.100	40.960	200.773	1.638	40.960	1.641
103.738	17.200	40.960	201.317	1.638	40.960	1.650
104.038	17.300	40.960	201.899	1.638	40.960	1.660
104.318	17.400	40.960	202.442	1.638	40.960	1.670
104.638	17.500	40.960	203.063	1.638	40.960	1.680
104.958	17.600	40.960	203.684	1.638	40.960	1.691
105.225	17.700	40.960	204.201	1.638	40.960	1.700
105.518	17.800	40.960	204.771	1.638	40.960	1.710
105.818	17.900	40.960	205.353	1.638	40.960	1.720
106.078	18.000	40.960	205.857	1.638	40.960	1.730
106.398	18.100	40.960	206.478	1.638	40.960	1.741
106.638	18.200	40.960	206.944	1.638	40.960	1.750
106.938	18.300	40.960	207.526	1.638	40.960	1.760
107.258	18.400	40.960	208.147	1.638	40.960	1.771
107.518	18.500	40.960	208.652	1.638	40.960	1.780
107.841	18.600	40.960	209.278	1.638	40.960	1.790
108.118	18.700	40.960	209.816	1.638	40.960	1.800
108.358	18.800	40.960	210.282	1.638	40.960	1.809
108.668	18.900	40.960	210.884	1.638	40.960	1.820
108.923	19.000	40.960	211.378	1.638	40.960	1.830
109.258	19.100	40.960	212.029	1.638	40.960	1.841
109.478	19.200	40.960	212.455	1.638	40.960	1.850
109.738	19.300	40.960	212.960	1.638	40.960	1.859
110.038	19.400	40.960	213.542	1.638	40.960	1.871
110.298	19.500	40.960	214.047	1.638	40.960	1.880
110.561	19.600	40.960	214.556	1.638	40.960	1.890
110.836	19.700	40.960	215.090	1.638	40.960	1.900
111.058	19.800	40.960	215.522	1.638	40.960	1.909
111.343	19.900	40.960	216.075	1.638	40.960	1.920
111.618	20.000	40.960	216.608	1.638	40.960	1.930
111.858	20.100	40.960	217.074	1.638	40.960	1.941
112.127	20.200	40.960	217.596	1.638	40.960	1.950
112.338	20.300	40.960	218.006	1.638	40.960	1.960
112.578	20.400	40.960	218.471	1.638	40.960	1.970
112.823	20.500	40.960	218.947	1.638	40.960	1.980
113.038	20.600	40.960	219.364	1.638	40.960	1.991
113.247	20.700	40.960	219.769	1.638	40.960	2.000
113.518	20.800	40.960	220.295	1.638	40.960	2.011
113.778	20.900	40.960	220.800	1.638	40.960	2.021
114.076	21.000	40.960	221.377	1.638	40.960	2.031
114.378	21.100	40.960	221.964	1.638	40.960	2.041
114.644	21.200	40.960	222.481	1.638	40.960	2.050
114.918	21.300	40.960	223.012	1.638	40.960	2.060
115.238	21.400	40.960	223.633	1.638	40.960	2.070
115.543	21.500	40.960	224.225	1.638	40.960	2.081
115.858	21.600	40.960	224.836	1.638	40.960	2.091
116.124	21.700	40.960	225.353	1.638	40.960	2.100
116.418	21.800	40.960	225.923	1.638	40.960	2.110
116.758	21.900	40.960	226.583	1.638	40.960	2.121
116.958	22.000	40.960	226.971	1.638	40.960	2.130
117.242	22.100	40.960	227.522	1.638	40.960	2.140
117.544	22.200	40.960	228.109	1.638	40.960	2.150
117.798	22.300	40.960	228.601	1.638	40.960	2.159
118.118	22.400	40.960	229.222	1.638	40.960	2.171
118.331	22.500	40.960	229.635	1.638	40.960	2.180
118.582	22.600	40.960	230.122	1.638	40.960	2.190
118.858	22.700	40.960	230.658	1.638	40.960	2.200
119.098	22.800	40.960	231.124	1.638	40.960	2.209
119.418	22.900	40.960	231.745	1.638	40.960	2.221
119.643	23.000	40.960	232.182	1.638	40.960	2.230
119.998	23.100	40.960	232.870	1.638	40.960	2.241
120.227	23.200	40.960	233.314	1.638	40.960	2.250
120.558	23.300	40.960	233.957	1.638	40.960	2.260
120.878	23.400	40.960	234.578	1.638	40.960	2.271
121.196	23.500	40.960	235.194	1.638	40.960	2.280
121.558	23.600	40.960	235.898	1.638	40.960	2.291
121.867	23.700	40.960	236.497	1.638	40.960	2.300
122.158	23.800	40.960	237.062	1.638	40.960	2.310
122.518	23.900	40.960	237.761	1.638	40.960	2.321
122.783	24.000	40.960	238.275	1.638	40.960	2.330
123.118	24.100	40.960	238.925	1.638	40.960	2.341
123.384	24.200	40.960	239.442	1.638	40.960	2.350
123.654	24.300	40.960	239.966	1.638	40.960	2.360
123.943	24.400	40.960	240.526	1.638	40.960	2.370
124.218	24.500	40.960	241.060	1.638	40.960	2.380
124.478	24.600	40.960	241.564	1.638	40.960	2.390
124.716	24.700	40.960	242.025	1.638	40.960	2.400
124.918	24.800	40.960	242.418	1.638	40.960	2.409
125.138	24.900	40.960	242.845	1.638	40.960	2.420
125.351	25.000	40.960	243.257	1.638	40.960	2.431
125.558	25.100	40.960	243.660	1.638	40.960	2.441
125.747	25.200	40.960	244.026	1.638	40.960	2.449
125.978	25.300	40.960	244.475	1.638	40.960	2.459
126.223	25.400	40.960	244.951	1.638	40.960	2.470
126.478	25.500	40.960	245.445	1.638	40.960	2.479
126.699	25.600	40.960	245.875	1.638	40.960	2.491
126.964	25.700	40.960	246.389	1.638	40.960	2.499
127.238	25.800	40.960	246.920	1.638	40.960	2.510
127.558	25.900	40.960	247.541	1.638	40.960	2.520
127.828	26.000	40.960	248.065	1.638	40.960	2.529
128.098	26.100	40.960	248.589	1.638	40.960	2.541
128.318	26.200	40.960	249.016	1.638	40.960	2.550
128.554	26.300	40.960	249.475	1.638	40.960	2.560
128.858	26.400	40.960	250.064	1.638	40.960	2.570
129.118	26.500	40.960	250.569	1.638	40.960	2.580
129.382	26.600	40.960	251.080	1.638	40.960	2.589
129.635	26.700	40.960	251.573	1.638	40.960	2.599
129.878	26.800	40.960	252.043	1.638	40.960	2.611
130.143	26.900	40.960	252.558	1.638	40.960	2.621
130.338	27.000	40.960	252.936	1.638	40.960	2.630
130.640	27.100	40.960	253.523	1.638	40.960	2.639
130.887	27.200	40.960	254.001	1.638	40.960	2.650
131.098	27.300	40.960	254.411	1.638	40.960	2.659
131.398	27.400	40.960	254.993	1.638	40.960	2.670
131.658	27.500	40.960	255.498	1.638	40.960	2.679
131.938	27.600	40.960	256.041	1.638	40.960	2.690
132.187	27.700	40.960	256.524	1.638	40.960	2.699
132.458	27.800	40.960	257.050	1.638	40.960	2.710
132.728	27.900	40.960	257.574	1.638	40.960	2.720
133.018	28.000	40.960	258.137	1.638	40.960	2.729
133.322	28.100	40.960	258.726	1.638	40.960	2.739
133.618	28.200	40.960	259.301	1.638	40.960	2.749
133.898	28.300	40.960	259.845	1.638	40.960	2.759
134.218	28.400	40.960	260.466	1.638	40.960	2.770
134.475	28.500	40.960	260.965	1.638	40.960	2.779
134.818	28.600	40.960	261.630	1.638	40.960	2.791
135.058	28.700	40.960	262.096	1.638	40.960	2.800
135.378	28.800	40.960	262.717	1.638	40.960	2.811
135.678	28.900	40.960	263.299	1.638	40.960	2.819
135.958	29.000	40.960	263.842	1.638	40.960	2.829
136.278	29.100	40.960	264.463	1.638	40.960	2.840
136.567	29.200	40.960	265.024	1.638	40.960	2.850
136.818	29.300	40.960	265.511	1.638	40.960	2.858
137.148	29.400	40.960	266.152	1.638	40.960	2.870
137.480	29.500	40.960	266.797	1.638	40.960	2.880
137.778	29.600	40.960	267.374	1.638	40.960	2.890
138.038	29.700	40.960	267.879	1.638	40.960	2.899
138.338	29.800	40.960	268.461	1.638	40.960	2.909
138.678	29.900	40.960	269.121	1.638	40.960	2.920
138.995	30.000	40.960	269.737	1.638	40.960	2.929
139.359	30.100	40.960	270.443	1.638	40.960	2.940
139.755	30.200	40.960	271.212	1.638	40.960	2.949
140.118	30.300	40.960	271.915	1.638	40.960	2.959
140.458	30.400	40.960	272.575	1.638	40.960	2.969
140.810	30.500	40.960	273.259	1.638	40.960	2.980
141.118	30.600	40.960	273.856	1.638	40.960	2.990
141.438	30.700	40.960	274.477	1.638	40.960	2.999
141.718	30.800	40.960	275.020	1.638	40.960	3.008
142.103	30.900	40.960	275.767	1.638	40.960	3.019
142.408	31.000	40.960	276.359	1.638	40.960	3.030
142.720	31.100	40.960	276.965	1.638	40.960	3.040
143.006	31.200	40.960	277.521	1.638	40.960	3.050
143.298	31.300	40.960	278.086	1.638	40.960	3.061
143.638	31.400	40.960	278.746	1.638	40.960	3.070
143.898	31.500	40.960	279.251	1.638	40.960	3.079
144.218	31.600	40.960	279.871	1.638	40.960	3.090
144.498	31.700	40.960	280.415	1.638	40.960	3.100
144.778	31.800	40.960	280.958	1.638	40.960	3.111
145.078	31.900	40.960	281.540	1.638	40.960	3.121
145.358	32.000	40.960	282.084	1.638	40.960	3.129
145.638	32.100	40.960	282.627	1.638	40.960	3.140
145.875	32.200	40.960	283.088	1.638	40.960	3.149
146.138	32.300	40.960	283.597	1.638	40.960	3.160
146.458	32.400	40.960	284.218	1.638	40.960	3.170
146.678	32.500	40.960	284.645	1.638	40.960	3.179
146.961	32.600	40.960	285.196	1.638	40.960	3.189
147.218	32.700	40.960	285.693	1.638	40.960	3.199
147.498	32.800	40.960	286.237	1.638	40.960	3.208
147.783	32.900	40.960	286.790	1.638	40.960	3.219
148.030	33.000	40.960	287.270	1.638	40.960	3.229
148.298	33.100	40.960	287.789	1.638	40.960	3.240
148.518	33.200	40.960	288.216	1.638	40.960	3.249
148.738	33.300	40.960	288.643	1.638	40.960	3.258
149.043	33.400	40.960	289.235	1.638	40.960	3.269
149.318	33.500	40.960	289.768	1.638	40.960	3.279
149.599	33.600	40.960	290.314	1.638	40.960	3.291
149.818	33.700	40.960	290.739	1.638	40.960	3.300
150.078	33.800	40.960	291.243	1.638	40.960	3.309
150.348	33.900	40.960	291.767	1.638	40.960	3.319
150.635	34.000	40.960	292.325	1.638	40.960	3.329
150.918	34.100	40.960	292.873	1.638	40.960	3.340
151.175	34.200	40.960	293.373	1.638	40.960	3.350
151.418	34.300	40.960	293.844	1.638	40.960	3.359
151.698	34.400	40.960	294.387	1.638	40.960	3.370
151.930	34.500	40.960	294.838	1.638	40.960	3.379
152.258	34.600	40.960	295.474	1.638	40.960	3.390
152.458	34.700	40.960	295.862	1.638	40.960	3.399
152.718	34.800	40.960	296.366	1.638	40.960	3.408
153.038	34.900	40.960	296.987	1.638	40.960	3.420
153.258	35.000	40.960	297.414	1.638	40.960	3.429
153.521	35.100	40.960	297.926	1.638	40.960	3.439
153.806	35.200	40.960	298.479	1.638	40.960	3.449
154.058	35.300	40.960	298.967	1.638	40.960	3.459
154.318	35.400	40.960	299.471	1.638	40.960	3.469
154.583	35.500	40.960	299.986	1.638	40.960	3.480
154.838	35.600	40.960	300.481	1.638	40.960	3.490
155.058	35.700	40.960	300.907	1.638	40.960	3.499
155.298	35.800	40.960	301.373	1.638	40.960	3.508
155.563	35.900	40.960	301.887	1.638	40.960	3.519
155.838	36.000	40.960	302.421	1.638	40.960	3.530
156.100	36.100	40.960	302.931	1.638	40.960	3.539
156.318	36.200	40.960	303.353	1.638	40.960	3.549
156.558	36.300	40.960	303.818	1.638	40.960	3.559
156.798	36.400	40.960	304.284	1.638	40.960	3.569
157.018	36.500	40.960	304.711	1.638	40.960	3.579
157.317	36.600	40.960	305.293	1.638	40.960	3.590
157.546	36.700	40.960	305.737	1.638	40.960	3.599
157.757	36.800	40.960	306.147	1.638	40.960	3.608
158.022	36.900	40.960	306.661	1.638	40.960	3.619
158.237	37.000	40.960	307.079	1.638	40.960	3.629
158.497	37.100	40.960	307.583	1.638	40.960	3.640
158.726	37.200	40.960	308.027	1.638	40.960	3.649
158.937	37.300	40.960	308.437	1.638	40.960	3.658
159.222	37.400	40.960	308.990	1.638	40.960	3.669
159.437	37.500	40.960	309.407	1.638	40.960	3.679
159.637	37.600	40.960	309.795	1.638	40.960	3.690
159.855	37.700	40.960	310.217	1.638	40.960	3.699
160.077	37.800	40.960	310.649	1.638	40.960	3.709
160.297	37.900	40.960	311.076	1.638	40.960	3.719
160.590	38.000	40.960	311.644	1.638	40.960	3.730
160.819	38.100	40.960	312.088	1.638	40.960	3.739
161.066	38.200	40.960	312.568	1.638	40.960	3.749
161.297	38.300	40.960	313.017	1.638	40.960	3.758
161.597	38.400	40.960	313.599	1.638	40.960	3.770
161.815	38.500	40.960	314.021	1.638	40.960	3.779
162.077	38.600	40.960	314.530	1.638	40.960	3.790
162.257	38.700	40.960	314.880	1.638	40.960	3.799
162.517	38.800	40.960	315.384	1.638	40.960	3.810
162.737	38.900	40.960	315.811	1.638	40.960	3.819
162.970	39.000	40.960	316.262	1.638	40.960	3.830
163.201	39.100	40.960	316.711	1.638	40.960	3.839
163.466	39.200	40.960	317.225	1.638	40.960	3.849
163.677	39.300	40.960	317.635	1.638	40.960	3.858
163.977	39.400	40.960	318.217	1.638	40.960	3.869
164.257	39.500	40.960	318.761	1.638	40.960	3.880
164.557	39.600	40.960	319.343	1.638	40.960	3.890
164.795	39.700	40.960	319.804	1.638	40.960	3.899
165.057	39.800	40.960	320.313	1.638	40.960	3.909
165.407	39.900	40.960	320.993	1.638	40.960	3.920
165.650	40.000	40.960	321.463	1.638	40.960	3.929
165.939	40.100	40.960	322.023	1.638	40.960	3.940
166.226	40.200	40.960	322.581	1.638	40.960	3.949
166.457	40.300	40.960	323.030	1.638	40.960	3.958
166.742	40.400	40.960	323.583	1.638	40.960	3.969
166.997	40.500	40.960	324.078	1.638	40.960	3.979
167.280	40.600	40.960	324.626	1.638	40.960	3.990
167.526	40.700	40.960	325.104	1.638	40.960	3.999
167.810	40.800	40.960	325.655	1.638	40.960	4.009
168.037	40.900	40.960	326.096	1.638	40.960	4.019
168.282	41.000	40.960	326.572	1.638	40.960	4.029
168.561	41.100	40.960	327.113	1.638	40.960	4.039
168.797	41.200	40.960	327.571	1.638	40.960	4.050
169.037	41.300	40.960	328.037	1.638	40.960	4.060
169.297	41.400	40.960	328.541	1.638	40.960	4.069
169.557	41.500	40.960	329.046	1.638	40.960	4.079
169.817	41.600	40.960	329.551	1.638	40.960	4.090
170.017	41.700	40.960	329.939	1.638	40.960	4.100
170.257	41.800	40.960	330.404	1.638	40.960	4.110
170.517	41.900	40.960	330.909	1.638	40.960	4.120
170.755	42.000	40.960	331.370	1.638	40.960	4.130
171.001	42.100	40.960	331.848	1.638	40.960	4.140
171.246	42.200	40.960	332.323	1.638	40.960	4.149
171.457	42.300	40.960	332.733	1.638	40.960	4.159
171.757	42.400	40.960	333.315	1.638	40.960	4.171
172.002	42.500	40.960	333.791	1.638	40.960	4.180
172.277	42.600	40.960	334.324	1.638	40.960	4.191
172.497	42.700	40.960	334.751	1.638	40.960	4.200
172.737	42.800	40.960	335.217	1.638	40.960	4.209
173.007	42.900	40.960	335.741	1.638	40.960	4.221
173.277	43.000	40.960	336.265	1.638	40.960	4.230
173.557	43.100	40.960	336.808	1.638	40.960	4.241
173.777	43.200	40.960	337.235	1.638	40.960	4.250
174.057	43.300	40.960	337.779	1.638	40.960	4.260
174.357	43.400	40.960	338.361	1.638	40.960	4.271
174.617	43.500	40.960	338.865	1.638	40.960	4.280
174.880	43.600	40.960	339.375	1.638	40.960	4.290
175.135	43.700	40.960	339.870	1.638	40.960	4.300
175.357	43.800	40.960	340.301	1.638	40.960	4.309
175.667	43.900	40.960	340.903	1.638	40.960	4.320
175.902	44.000	40.960	341.359	1.638	40.960	4.330
176.197	44.100	40.960	341.931	1.638	40.960	4.341
176.437	44.200	40.960	342.397	1.638	40.960	4.350
176.657	44.300	40.960	342.824	1.638	40.960	4.359
176.937	44.400	40.960	343.368	1.638	40.960	4.370
177.177	44.500	40.960	343.833	1.638	40.960	4.380
177.460	44.600	40.960	344.381	1.638	40.960	4.390
177.677	44.700	40.960	344.804	1.638	40.960	4.399
177.957	44.800	40.960	345.347	1.638	40.960	4.409
178.157	44.900	40.960	345.735	1.638	40.960	4.419
178.422	45.000	40.960	346.249	1.638	40.960	4.430
178.657	45.100	40.960	346.705	1.638	40.960	4.441
178.863	45.200	40.960	347.106	1.638	40.960	4.449
179.130	45.300	40.960	347.622	1.638	40.960	4.460
179.397	45.400	40.960	348.141	1.638	40.960	4.470
179.617	45.500	40.960	348.568	1.638	40.960	4.479
179.857	45.600	40.960	349.034	1.638	40.960	4.490
180.057	45.700	40.960	349.422	1.638	40.960	4.499
180.297	45.800	40.960	349.888	1.638	40.960	4.509
180.562	45.900	40.960	350.402	1.638	40.960	4.520
180.762	46.000	40.960	350.790	1.638	40.960	4.529
181.017	46.100	40.960	351.285	1.638	40.960	4.540
181.257	46.200	40.960	351.751	1.638	40.960	4.549
181.497	46.300	40.960	352.217	1.638	40.960	4.559
181.757	46.400	40.960	352.721	1.638	40.960	4.570
181.930	46.500	40.960	353.056	1.638	40.960	4.579
182.200	46.600	40.960	353.580	1.638	40.960	4.589
182.437	46.700	40.960	354.041	1.638	40.960	4.599
182.677	46.800	40.960	354.506	1.638	40.960	4.609
182.977	46.900	40.960	355.089	1.638	40.960	4.620
183.197	47.000	40.960	355.516	1.638	40.960	4.629
183.480	47.100	40.960	356.064	1.638	40.960	4.639
183.786	47.200	40.960	356.658	1.638	40.960	4.649
184.030	47.300	40.960	357.131	1.638	40.960	4.659
184.337	47.400	40.960	357.728	1.638	40.960	4.670
184.610	47.500	40.960	358.257	1.638	40.960	4.679
184.917	47.600	40.960	358.853	1.638	40.960	4.690
185.163	47.700	40.960	359.331	1.638	40.960	4.699
185.437	47.800	40.960	359.863	1.638	40.960	4.708
185.737	47.900	40.960	360.445	1.638	40.960	4.720
186.007	48.000	40.960	360.969	1.638	40.960	4.729
186.280	48.100	40.960	361.497	1.638	40.960	4.739
186.546	48.200	40.960	362.014	1.638	40.960	4.749
186.797	48.300	40.960	362.502	1.638	40.960	4.759
187.097	48.400	40.960	363.084	1.638	40.960	4.770
187.357	48.500	40.960	363.588	1.638	40.960	4.779
187.637	48.600	40.960	364.132	1.638	40.960	4.790
187.897	48.700	40.960	364.636	1.638	40.960	4.799
188.137	48.800	40.960	365.102	1.638	40.960	4.809
188.397	48.900	40.960	365.607	1.638	40.960	4.819
188.709	49.000	40.960	366.213	1.638	40.960	4.830
188.959	49.100	40.960	366.698	1.638	40.960	4.839
189.223	49.200	40.960	367.210	1.638	40.960	4.849
189.493	49.300	40.960	367.734	1.638	40.960	4.859
189.817	49.400	40.960	368.362	1.638	40.960	4.870
190.107	49.500	40.960	368.925	1.638	40.960	4.879
190.397	49.600	40.960	369.488	1.638	40.960	4.890
190.603	49.700	40.960	369.888	1.638	40.960	4.899
190.977	49.800	40.960	370.613	1.638	40.960	4.909
191.267	49.900	40.960	371.176	1.638	40.960	4.920
191.537	50.000	40.960	371.700	1.638	40.960	4.929
191.837	50.100	40.960	372.282	1.638	40.960	4.940
192.054	50.200	40.960	372.704	1.638	40.960	4.949
192.337	50.300	40.960	373.253	1.638	40.960	4.959
192.617	50.400	40.960	373.796	1.638	40.960	4.969
192.877	50.500	40.960	374.300	1.638	40.960	4.979
193.137	50.600	40.960	374.805	1.638	40.960	4.989
193.414	50.700	40.960	375.344	1.638	40.960	4.999
193.717	50.800	40.960	375.931	1.638	40.960	5.009
193.977	50.900	40.960	376.435	1.638	40.960	5.019
194.262	51.000	40.960	376.988	1.638	40.960	5.029
194.521	51.100	40.960	377.490	1.638	40.960	5.039
194.806	51.200	40.960	378.043	1.638	40.960	5.049
195.037	51.300	40.960	378.492	1.638	40.960	5.059
195.337	51.400	40.960	379.074	1.638	40.960	5.070
195.594	51.500	40.960	379.574	1.638	40.960	5.079
195.877	51.600	40.960	380.122	1.638	40.960	5.090
196.117	51.700	40.960	380.588	1.638	40.960	5.099
196.369	51.800	40.960	381.078	1.638	40.960	5.109
196.657	51.900	40.960	381.636	1.638	40.960	5.120
196.894	52.000	40.960	382.097	1.638	40.960	5.129
197.142	52.100	40.960	382.577	1.638	40.960	5.139
197.466	52.200	40.960	383.205	1.638	40.960	5.149
197.693	52.300	40.960	383.647	1.638	40.960	5.159
197.962	52.400	40.960	384.168	1.638	40.960	5.169
198.197	52.500	40.960	384.624	1.638	40.960	5.179
198.457	52.600	40.960	385.129	1.638	40.960	5.190
198.657	52.700	40.960	385.517	1.638	40.960	5.199
198.937	52.800	40.960	386.060	1.638	40.960	5.209
199.217	52.900	40.960	386.604	1.638	40.960	5.220
199.429	53.000	40.960	387.016	1.638	40.960	5.229
199.681	53.100	40.960	387.504	1.638	40.960	5.239
199.917	53.200	40.960	387.962	1.638	40.960	5.249
200.137	53.300	40.960	388.389	1.638	40.960	5.258
200.417	53.400	40.960	388.932	1.638	40.960	5.269
200.677	53.500	40.960	389.437	1.638	40.960	5.279
200.937	53.600	40.960	389.942	1.638	40.960	5.290
201.137	53.700	40.960	390.330	1.638	40.960	5.299
201.397	53.800	40.960	390.834	1.638	40.960	5.309
201.637	53.900	40.960	391.300	1.638	40.960	5.319
201.874	54.000	40.960	391.761	1.638	40.960	5.329
202.157	54.100	40.960	392.309	1.638	40.960	5.340
202.337	54.200	40.960	392.658	1.638	40.960	5.349
202.597	54.300	40.960	393.163	1.638	40.960	5.359
202.857	54.400	40.960	393.668	1.638	40.960	5.370
203.057	54.500	40.960	394.056	1.638	40.960	5.379
203.322	54.600	40.960	394.570	1.638	40.960	5.389
203.577	54.700	40.960	395.065	1.638	40.960	5.399
203.837	54.800	40.960	395.569	1.638	40.960	5.409
204.077	54.900	40.960	396.035	1.638	40.960	5.420
204.297	55.000	40.960	396.462	1.638	40.960	5.429
204.559	55.100	40.960	396.971	1.638	40.960	5.439
204.817	55.200	40.960	397.471	1.638	40.960	5.449
205.017	55.300	40.960	397.859	1.638	40.960	5.458
205.317	55.400	40.960	398.441	1.638	40.960	5.469
205.557	55.500	40.960	398.907	1.638	40.960	5.480
205.837	55.600	40.960	399.450	1.638	40.960	5.490
206.034	55.700	40.960	399.834	1.638	40.960	5.499
206.297	55.800	40.960	400.343	1.638	40.960	5.509
206.547	55.900	40.960	400.828	1.638	40.960	5.519
206.817	56.000	40.960	401.352	1.638	40.960	5.529
207.058	56.100	40.960	401.820	1.638	40.960	5.539
207.283	56.200	40.960	402.257	1.638	40.960	5.549
207.537	56.300	40.960	402.749	1.638	40.960	5.559
207.817	56.400	40.960	403.293	1.638	40.960	5.570
208.034	56.500	40.960	403.715	1.638	40.960	5.579
208.277	56.600	40.960	404.186	1.638	40.960	5.590
208.497	56.700	40.960	404.612	1.638	40.960	5.599
208.709	56.800	40.960	405.025	1.638	40.960	5.609
208.957	56.900	40.960	405.505	1.638	40.960	5.620
209.194	57.000	40.960	405.966	1.638	40.960	5.629
209.420	57.100	40.960	406.405	1.638	40.960	5.639
209.697	57.200	40.960	406.941	1.638	40.960	5.649
209.917	57.300	40.960	407.368	1.638	40.960	5.660
210.157	57.400	40.960	407.834	1.638	40.960	5.670
210.394	57.500	40.960	408.295	1.638	40.960	5.679
210.638	57.600	40.960	408.768	1.638	40.960	5.689
210.857	57.700	40.960	409.192	1.638	40.960	5.699
211.057	57.800	40.960	409.580	1.638	40.960	5.708
211.337	57.900	40.960	410.124	1.638	40.960	5.719
211.557	58.000	40.960	410.551	1.638	40.960	5.729
211.817	58.100	40.960	411.055	1.638	40.960	5.740
212.005	58.200	40.960	411.421	1.638	40.960	5.749
212.177	58.300	40.960	411.754	1.638	40.960	5.758
212.417	58.400	40.960	412.220	1.638	40.960	5.769
212.642	58.500	40.960	412.656	1.638	40.960	5.779
212.840	58.600	40.960	413.042	1.638	40.960	5.789
213.077	58.700	40.960	413.500	1.638	40.960	5.799
213.253	58.800	40.960	413.842	1.638	40.960	5.809
213.507	58.900	40.960	414.335	1.638	40.960	5.819
213.714	59.000	40.960	414.737	1.638	40.960	5.829
213.959	59.100	40.960	415.213	1.638	40.960	5.839
214.183	59.200	40.960	415.647	1.638	40.960	5.849
214.397	59.300	40.960	416.062	1.638	40.960	5.858
214.637	59.400	40.960	416.528	1.638	40.960	5.869
214.874	59.500	40.960	416.989	1.638	40.960	5.879
215.137	59.600	40.960	417.498	1.638	40.960	5.890
215.334	59.700	40.960	417.881	1.638	40.960	5.899
215.577	59.800	40.960	418.352	1.638	40.960	5.909
215.857	59.900	40.960	418.895	1.638	40.960	5.920
216.102	60.000	40.960	419.371	1.638	40.960	5.930
216.357	60.100	40.960	419.865	1.638	40.960	5.940
216.634	60.200	40.960	420.404	1.638	40.960	5.949
216.857	60.300	40.960	420.836	1.638	40.960	5.958
217.117	60.400	40.960	421.340	1.638	40.960	5.969
217.389	60.500	40.960	421.869	1.638	40.960	5.980
217.637	60.600	40.960	422.349	1.638	40.960	5.990
217.857	60.700	40.960	422.776	1.638	40.960	5.999
218.097	60.800	40.960	423.242	1.638	40.960	6.009
218.377	60.900	40.960	423.785	1.638	40.960	6.019
218.617	61.000	40.960	424.251	1.638	40.960	6.030
218.857	61.100	40.960	424.717	1.638	40.960	6.040
219.085	61.200	40.960	425.161	1.638	40.960	6.049
219.277	61.300	40.960	425.532	1.638	40.960	6.058
219.547	61.400	40.960	426.056	1.638	40.960	6.069
219.794	61.500	40.960	426.536	1.638	40.960	6.079
220.058	61.600	40.960	427.048	1.638	40.960	6.090
220.274	61.700	40.960	427.468	1.638	40.960	6.099
220.496	61.800	40.960	427.899	1.638	40.960	6.109
220.756	61.900	40.960	428.404	1.638	40.960	6.120
220.956	62.000	40.960	428.792	1.638	40.960	6.129
221.199	62.100	40.960	429.263	1.638	40.960	6.140
221.456	62.200	40.960	429.762	1.638	40.960	6.149
221.636	62.300	40.960	430.112	1.638	40.960	6.158
221.886	62.400	40.960	430.597	1.638	40.960	6.169
222.129	62.500	40.960	431.067	1.638	40.960	6.179
222.380	62.600	40.960	431.555	1.638	40.960	6.189
222.576	62.700	40.960	431.936	1.638	40.960	6.199
222.836	62.800	40.960	432.440	1.638	40.960	6.209
223.096	62.900	40.960	432.945	1.638	40.960	6.220
223.321	63.000	40.960	433.382	1.638	40.960	6.229
223.596	63.100	40.960	433.915	1.638	40.960	6.240
223.794	63.200	40.960	434.299	1.638	40.960	6.249
224.053	63.300	40.960	434.801	1.638	40.960	6.259
224.276	63.400	40.960	435.235	1.638	40.960	6.269
224.561	63.500	40.960	435.788	1.638	40.960	6.279
224.816	63.600	40.960	436.283	1.638	40.960	6.290
225.016	63.700	40.960	436.671	1.638	40.960	6.299
225.216	63.800	40.960	437.059	1.638	40.960	6.309
225.461	63.900	40.960	437.535	1.638	40.960	6.320
225.694	64.000	40.960	437.986	1.638	40.960	6.329
225.936	64.100	40.960	438.456	1.638	40.960	6.340
226.154	64.200	40.960	438.878	1.638	40.960	6.349
226.336	64.300	40.960	439.233	1.638	40.960	6.358
226.621	64.400	40.960	439.786	1.638	40.960	6.369
226.816	64.500	40.960	440.164	1.638	40.960	6.379
227.096	64.600	40.960	440.707	1.638	40.960	6.390
227.283	64.700	40.960	441.069	1.638	40.960	6.399
227.516	64.800	40.960	441.522	1.638	40.960	6.408
227.796	64.900	40.960	442.066	1.638	40.960	6.420
228.016	65.000	40.960	442.493	1.638	40.960	6.429
228.276	65.100	40.960	442.997	1.638	40.960	6.440
228.494	65.200	40.960	443.419	1.638	40.960	6.449
228.729	65.300	40.960	443.875	1.638	40.960	6.459
228.976	65.400	40.960	444.356	1.638	40.960	6.469
229.216	65.500	40.960	444.821	1.638	40.960	6.479
229.516	65.600	40.960	445.404	1.638	40.960	6.490
229.736	65.700	40.960	445.831	1.638	40.960	6.499
230.016	65.800	40.960	446.374	1.638	40.960	6.509
230.256	65.900	40.960	446.840	1.638	40.960	6.519
230.554	66.000	40.960	447.417	1.638	40.960	6.529
230.816	66.100	40.960	447.926	1.638	40.960	6.540
231.056	66.200	40.960	448.392	1.638	40.960	6.549
231.296	66.300	40.960	448.858	1.638	40.960	6.559
231.606	66.400	40.960	449.459	1.638	40.960	6.569
231.861	66.500	40.960	449.954	1.638	40.960	6.579
232.136	66.600	40.960	450.488	1.638	40.960	6.590
232.376	66.700	40.960	450.954	1.638	40.960	6.599
232.656	66.800	40.960	451.497	1.638	40.960	6.609
232.916	66.900	40.960	452.002	1.638	40.960	6.619
233.214	67.000	40.960	452.579	1.638	40.960	6.629
233.516	67.100	40.960	453.166	1.638	40.960	6.640
233.765	67.200	40.960	453.649	1.638	40.960	6.649
234.016	67.300	40.960	454.136	1.638	40.960	6.660
234.336	67.400	40.960	454.757	1.638	40.960	6.670
234.589	67.500	40.960	455.247	1.638	40.960	6.680
234.856	67.600	40.960	455.766	1.638	40.960	6.690
235.071	67.700	40.960	456.184	1.638	40.960	6.699
235.356	67.800	40.960	456.737	1.638	40.960	6.709
235.656	67.900	40.960	457.319	1.638	40.960	6.720
235.901	68.000	40.960	457.794	1.638	40.960	6.730
236.119	68.100	40.960	458.216	1.638	40.960	6.740
236.376	68.200	40.960	458.716	1.638	40.960	6.749
236.649	68.300	40.960	459.245	1.638	40.960	6.759
236.876	68.400	40.960	459.686	1.638	40.960	6.769
237.169	68.500	40.960	460.254	1.638	40.960	6.780
237.439	68.600	40.960	460.778	1.638	40.960	6.789
237.705	68.700	40.960	461.295	1.638	40.960	6.799
237.916	68.800	40.960	461.705	1.638	40.960	6.808
238.256	68.900	40.960	462.364	1.638	40.960	6.820
238.516	69.000	40.960	462.869	1.638	40.960	6.829
238.757	69.100	40.960	463.337	1.638	40.960	6.840
239.036	69.200	40.960	463.878	1.638	40.960	6.849
239.296	69.300	40.960	464.383	1.638	40.960	6.860
239.561	69.400	40.960	464.897	1.638	40.960	6.869
239.839	69.500	40.960	465.435	1.638	40.960	6.879
240.119	69.600	40.960	465.979	1.638	40.960	6.889
240.382	69.700	40.960	466.490	1.638	40.960	6.899
240.656	69.800	40.960	467.022	1.638	40.960	6.909
240.956	69.900	40.960	467.604	1.638	40.960	6.920
241.206	70.000	40.960	468.089	1.638	40.960	6.929
241.480	70.100	40.960	468.620	1.638	40.960	6.939
241.736	70.200	40.960	469.118	1.638	40.960	6.949
242.136	70.300	40.960	469.894	1.638	40.960	6.959
242.421	70.400	40.960	470.447	1.638	40.960	6.969
242.676	70.500	40.960	470.942	1.638	40.960	6.979
242.941	70.600	40.960	471.456	1.638	40.960	6.989
243.225	70.700	40.960	472.007	1.638	40.960	6.999
243.456	70.800	40.960	472.455	1.638	40.960	7.009
243.741	70.900	40.960	473.008	1.638	40.960	7.019
243.976	71.000	40.960	473.464	1.638	40.960	7.029
244.240	71.100	40.960	473.976	1.638	40.960	7.039
244.502	71.200	40.960	474.486	1.638	40.960	7.049
244.736	71.300	40.960	474.939	1.638	40.960	7.058
245.041	71.400	40.960	475.531	1.638	40.960	7.069
245.289	71.500	40.960	476.012	1.638	40.960	7.080
245.540	71.600	40.960	476.499	1.638	40.960	7.089
245.805	71.700	40.960	477.013	1.638	40.960	7.099
246.036	71.800	40.960	477.462	1.638	40.960	7.109
246.336	71.900	40.960	478.044	1.638	40.960	7.120
246.556	72.000	40.960	478.471	1.638	40.960	7.129
246.817	72.100	40.960	478.978	1.638	40.960	7.140
247.071	72.200	40.960	479.471	1.638	40.960	7.149
247.316	72.300	40.960	479.946	1.638	40.960	7.159
247.576	72.400	40.960	480.451	1.638	40.960	7.170
247.814	72.500	40.960	480.911	1.638	40.960	7.179
248.076	72.600	40.960	481.421	1.638	40.960	7.190
248.302	72.700	40.960	481.860	1.638	40.960	7.199
248.589	72.800	40.960	482.415	1.638	40.960	7.209
248.836	72.900	40.960	482.896	1.638	40.960	7.219
249.056	73.000	40.960	483.323	1.638	40.960	7.229
249.297	73.100	40.960	483.791	1.638	40.960	7.239
249.554	73.200	40.960	484.288	1.638	40.960	7.249
249.756	73.300	40.960	484.681	1.638	40.960	7.258
250.036	73.400	40.960	485.224	1.638	40.960	7.269
250.314	73.500	40.960	485.763	1.638	40.960	7.279
250.577	73.600	40.960	486.275	1.638	40.960	7.290
250.802	73.700	40.960	486.711	1.638	40.960	7.299
251.016	73.800	40.960	487.126	1.638	40.960	7.309
251.256	73.900	40.960	487.592	1.638	40.960	7.319
251.516	74.000	40.960	488.097	1.638	40.960	7.329
251.817	74.100	40.960	488.681	1.638	40.960	7.340
252.025	74.200	40.960	489.084	1.638	40.960	7.349
252.232	74.300	40.960	489.486	1.638	40.960	7.359
252.476	74.400	40.960	489.959	1.638	40.960	7.369
252.721	74.500	40.960	490.435	1.638	40.960	7.379
252.996	74.600	40.960	490.969	1.638	40.960	7.390
253.222	74.700	40.960	491.408	1.638	40.960	7.399
253.468	74.800	40.960	491.886	1.638	40.960	7.409
253.701	74.900	40.960	492.337	1.638	40.960	7.419
253.928	75.000	40.960	492.778	1.638	40.960	7.429
254.216	75.100	40.960	493.336	1.638	40.960	7.440
254.436	75.200	40.960	493.763	1.638	40.960	7.449
254.636	75.300	40.960	494.151	1.638	40.960	7.459
254.916	75.400	40.960	494.695	1.638	40.960	7.470
255.141	75.500	40.960	495.131	1.638	40.960	7.479
255.416	75.600	40.960	495.665	1.638	40.960	7.490
255.613	75.700	40.960	496.048	1.638	40.960	7.499
255.868	75.800	40.960	496.543	1.638	40.960	7.509
256.116	75.900	40.960	497.023	1.638	40.960	7.519
256.336	76.000	40.960	497.450	1.638	40.960	7.529
256.597	76.100	40.960	497.957	1.638	40.960	7.539
256.796	76.200	40.960	498.343	1.638	40.960	7.549
257.036	76.300	40.960	498.809	1.638	40.960	7.559
257.296	76.400	40.960	499.313	1.638	40.960	7.570
257.536	76.500	40.960	499.779	1.638	40.960	7.579
257.778	76.600	40.960	500.249	1.638	40.960	7.589
257.976	76.700	40.960	500.633	1.638	40.960	7.599
258.196	76.800	40.960	501.060	1.638	40.960	7.608
258.441	76.900	40.960	501.535	1.638	40.960	7.619
258.676	77.000	40.960	501.991	1.638	40.960	7.630
258.918	77.100	40.960	502.462	1.638	40.960	7.639
259.136	77.200	40.960	502.884	1.638	40.960	7.649
259.396	77.300	40.960	503.388	1.638	40.960	7.659
259.616	77.400	40.960	503.815	1.638	40.960	7.669
259.836	77.500	40.960	504.242	1.638	40.960	7.679
260.076	77.600	40.960	504.708	1.638	40.960	7.690
260.305	77.700	40.960	505.152	1.638	40.960	7.699
260.536	77.800	40.960	505.601	1.638	40.960	7.709
260.736	77.900	40.960	505.989	1.638	40.960	7.719
260.988	78.000	40.960	506.479	1.638	40.960	7.730
261.217	78.100	40.960	506.923	1.638	40.960	7.739
261.453	78.200	40.960	507.381	1.638	40.960	7.749
261.656	78.300	40.960	507.774	1.638	40.960	7.759
261.896	78.400	40.960	508.240	1.638	40.960	7.770
262.113	78.500	40.960	508.662	1.638	40.960	7.779
262.298	78.600	40.960	509.021	1.638	40.960	7.790
262.536	78.700	40.960	509.482	1.638	40.960	7.799
262.736	78.800	40.960	509.870	1.638	40.960	7.810
263.016	78.900	40.960	510.413	1.638	40.960	7.820
263.216	79.000	40.960	510.801	1.638	40.960	7.829
263.497	79.100	40.960	511.347	1.638	40.960	7.840
263.673	79.200	40.960	511.689	1.638	40.960	7.849
263.856	79.300	40.960	512.043	1.638	40.960	7.858
264.086	79.400	40.960	512.490	1.638	40.960	7.869
264.316	79.500	40.960	512.936	1.638	40.960	7.879
264.558	79.600	40.960	513.407	1.638	40.960	7.890
264.765	79.700	40.960	513.807	1.638	40.960	7.899
264.972	79.800	40.960	514.210	1.638	40.960	7.909
265.196	79.900	40.960	514.644	1.638	40.960	7.919
265.421	80.000	40.960	515.080	1.638	40.960	7.929
265.636	80.100	40.960	515.498	1.638	40.960	7.940
265.816	80.200	40.960	515.847	1.638	40.960	7.949
266.036	80.300	40.960	516.274	1.638	40.960	7.959
266.276	80.400	40.960	516.740	1.638	40.960	7.970
266.496	80.500	40.960	517.167	1.638	40.960	7.979
266.737	80.600	40.960	517.635	1.638	40.960	7.989
266.945	80.700	40.960	518.037	1.638	40.960	7.999
267.136	80.800	40.960	518.408	1.638	40.960	8.008
267.436	80.900	40.960	518.991	1.638	40.960	8.020
267.616	81.000	40.960	519.340	1.638	40.960	8.028
267.917	81.100	40.960	519.925	1.638	40.960	8.039
268.156	81.200	40.960	520.388	1.638	40.960	8.049
268.356	81.300	40.960	520.776	1.638	40.960	8.059
268.616	81.400	40.960	521.281	1.638	40.960	8.070
268.813	81.500	40.960	521.664	1.638	40.960	8.079
269.056	81.600	40.960	522.134	1.638	40.960	8.090
269.284	81.700	40.960	522.578	1.638	40.960	8.099
269.476	81.800	40.960	522.949	1.638	40.960	8.108
269.716	81.900	40.960	523.415	1.638	40.960	8.119
269.936	82.000	40.960	523.842	1.638	40.960	8.130
270.176	82.100	40.960	524.308	1.638	40.960	8.140
270.396	82.200	40.960	524.735	1.638	40.960	8.149
270.576	82.300	40.960	525.084	1.638	40.960	8.158
270.836	82.400	40.960	525.589	1.638	40.960	8.169
271.048	82.500	40.960	526.001	1.638	40.960	8.179
271.278	82.600	40.960	526.447	1.638	40.960	8.189
271.493	82.700	40.960	526.865	1.638	40.960	8.199
271.696	82.800	40.960	527.258	1.638	40.960	8.208
271.956	82.900	40.960	527.762	1.638	40.960	8.219
272.116	83.000	40.960	528.073	1.638	40.960	8.229
272.356	83.100	40.960	528.538	1.638	40.960	8.240
272.553	83.200	40.960	528.922	1.638	40.960	8.249
272.756	83.300	40.960	529.315	1.638	40.960	8.258
272.981	83.400	40.960	529.751	1.638	40.960	8.269
273.213	83.500	40.960	530.202	1.638	40.960	8.279
273.436	83.600	40.960	530.634	1.638	40.960	8.290
273.636	83.700	40.960	531.022	1.638	40.960	8.299
273.836	83.800	40.960	531.410	1.638	40.960	8.308
274.116	83.900	40.960	531.954	1.638	40.960	8.320
274.316	84.000	40.960	532.342	1.638	40.960	8.329
274.517	84.100	40.960	532.732	1.638	40.960	8.339
274.716	84.200	40.960	533.118	1.638	40.960	8.349
274.876	84.300	40.960	533.429	1.638	40.960	8.358
275.121	84.400	40.960	533.904	1.638	40.960	8.370
275.316	84.500	40.960	534.282	1.638	40.960	8.379
275.556	84.600	40.960	534.748	1.638	40.960	8.390
275.764	84.700	40.960	535.153	1.638	40.960	8.399
275.936	84.800	40.960	535.486	1.638	40.960	8.408
276.176	84.900	40.960	535.951	1.638	40.960	8.420
276.336	85.000	40.960	536.262	1.638	40.960	8.429
276.556	85.100	40.960	536.689	1.638	40.960	8.440
276.756	85.200	40.960	537.077	1.638	40.960	8.449
276.912	85.300	40.960	537.380	1.638	40.960	8.459
277.136	85.400	40.960	537.814	1.638	40.960	8.469
277.336	85.500	40.960	538.202	1.638	40.960	8.479
277.556	85.600	40.960	538.629	1.638	40.960	8.490
277.693	85.700	40.960	538.896	1.638	40.960	8.499
277.896	85.800	40.960	539.289	1.638	40.960	8.509
278.096	85.900	40.960	539.677	1.638	40.960	8.519
278.256	86.000	40.960	539.988	1.638	40.960	8.530
278.496	86.100	40.960	540.454	1.638	40.960	8.540
278.644	86.200	40.960	540.742	1.638	40.960	8.549
278.856	86.300	40.960	541.152	1.638	40.960	8.559
279.056	86.400	40.960	541.540	1.638	40.960	8.569
279.261	86.500	40.960	541.938	1.638	40.960	8.579
279.456	86.600	40.960	542.317	1.638	40.960	8.590
279.624	86.700	40.960	542.644	1.638	40.960	8.599
279.796	86.800	40.960	542.976	1.638	40.960	8.608
280.001	86.900	40.960	543.374	1.638	40.960	8.619
280.156	87.000	40.960	543.675	1.638	40.960	8.629
280.396	87.100	40.960	544.141	1.638	40.960	8.640
280.544	87.200	40.960	544.429	1.638	40.960	8.649
280.736	87.300	40.960	544.800	1.638	40.960	8.658
280.916	87.400	40.960	545.150	1.638	40.960	8.669
281.096	87.500	40.960	545.499	1.638	40.960	8.679
281.336	87.600	40.960	545.965	1.638	40.960	8.689
281.524	87.700	40.960	546.331	1.638	40.960	8.699
281.696	87.800	40.960	546.663	1.638	40.960	8.709
281.896	87.900	40.960	547.052	1.638	40.960	8.720
282.061	88.000	40.960	547.372	1.638	40.960	8.729
282.258	88.100	40.960	547.755	1.638	40.960	8.739
282.436	88.200	40.960	548.099	1.638	40.960	8.749
282.576	88.300	40.960	548.371	1.638	40.960	8.758
282.756	88.400	40.960	548.720	1.638	40.960	8.769
282.956	88.500	40.960	549.109	1.638	40.960	8.779
283.139	88.600	40.960	549.465	1.638	40.960	8.789
283.335	88.700	40.960	549.846	1.638	40.960	8.799
283.515	88.800	40.960	550.195	1.638	40.960	8.810
283.715	88.900	40.960	550.583	1.638	40.960	8.820
283.875	89.000	40.960	550.894	1.638	40.960	8.830
284.075	89.100	40.960	551.282	1.638	40.960	8.840
284.235	89.200	40.960	551.593	1.638	40.960	8.849
284.415	89.300	40.960	551.942	1.638	40.960	8.859
284.595	89.400	40.960	552.291	1.638	40.960	8.869
284.775	89.500	40.960	552.640	1.638	40.960	8.880
284.958	89.600	40.960	552.995	1.638	40.960	8.889
285.135	89.700	40.960	553.339	1.638	40.960	8.899
285.315	89.800	40.960	553.688	1.638	40.960	8.909
285.485	89.900	40.960	554.018	1.638	40.960	8.919
285.655	90.000	40.960	554.348	1.638	40.960	8.930
285.818	90.100	40.960	554.664	1.638	40.960	8.939
285.995	90.200	40.960	555.008	1.638	40.960	8.949
286.155	90.300	40.960	555.318	1.638	40.960	8.959
286.360	90.400	40.960	555.716	1.638	40.960	8.969
286.528	90.500	40.960	556.041	1.638	40.960	8.979
286.678	90.600	40.960	556.332	1.638	40.960	8.989
286.864	90.700	40.960	556.694	1.638	40.960	8.999
287.035	90.800	40.960	557.026	1.638	40.960	9.008
287.255	90.900	40.960	557.453	1.638	40.960	9.019
287.395	91.000	40.960	557.725	1.638	40.960	9.029
287.595	91.100	40.960	558.113	1.638	40.960	9.040
287.735	91.200	40.960	558.385	1.638	40.960	9.049
287.895	91.300	40.960	558.695	1.638	40.960	9.059
288.040	91.400	40.960	558.976	1.638	40.960	9.069
288.195	91.500	40.960	559.277	1.638	40.960	9.080
288.375	91.600	40.960	559.627	1.638	40.960	9.090
288.535	91.700	40.960	559.937	1.638	40.960	9.099
288.695	91.800	40.960	560.248	1.638	40.960	9.109
288.835	91.900	40.960	560.519	1.638	40.960	9.119
288.988	92.000	40.960	560.815	1.638	40.960	9.130
289.135	92.100	40.960	561.101	1.638	40.960	9.139
289.333	92.200	40.960	561.485	1.638	40.960	9.149
289.455	92.300	40.960	561.722	1.638	40.960	9.158
289.655	92.400	40.960	562.111	1.638	40.960	9.170
289.768	92.500	40.960	562.329	1.638	40.960	9.179
289.935	92.600	40.960	562.654	1.638	40.960	9.190
290.055	92.700	40.960	562.887	1.638	40.960	9.199
290.235	92.800	40.960	563.236	1.638	40.960	9.209
290.415	92.900	40.960	563.585	1.638	40.960	9.220
290.528	93.000	40.960	563.804	1.638	40.960	9.229
290.675	93.100	40.960	564.090	1.638	40.960	9.240
290.793	93.200	40.960	564.318	1.638	40.960	9.249
290.972	93.300	40.960	564.665	1.638	40.960	9.259
291.140	93.400	40.960	564.992	1.638	40.960	9.270
291.280	93.500	40.960	565.264	1.638	40.960	9.279
291.455	93.600	40.960	565.604	1.638	40.960	9.290
291.553	93.700	40.960	565.793	1.638	40.960	9.299
291.735	93.800	40.960	566.147	1.638	40.960	9.310
291.895	93.900	40.960	566.457	1.638	40.960	9.320
292.015	94.000	40.960	566.690	1.638	40.960	9.328
292.137	94.100	40.960	566.926	1.638	40.960	9.339
292.304	94.200	40.960	567.251	1.638	40.960	9.349
292.415	94.300	40.960	567.467	1.638	40.960	9.358
292.595	94.400	40.960	567.816	1.638	40.960	9.369
292.715	94.500	40.960	568.049	1.638	40.960	9.379
292.875	94.600	40.960	568.359	1.638	40.960	9.390
293.024	94.700	40.960	568.648	1.638	40.960	9.399
293.135	94.800	40.960	568.864	1.638	40.960	9.408
293.420	94.900	40.960	569.417	1.638	40.960	9.419
293.555	95.000	40.960	569.679	1.638	40.960	9.429
293.655	95.100	40.960	569.873	1.638	40.960	9.439
293.824	95.200	40.960	570.200	1.638	40.960	9.449
293.935	95.300	40.960	570.416	1.638	40.960	9.459
294.075	95.400	40.960	570.688	1.638	40.960	9.469
294.235	95.500	40.960	570.998	1.638	40.960	9.479
294.375	95.600	40.960	571.270	1.638	40.960	9.490
294.455	95.700	40.960	571.425	1.638	40.960	9.499
294.595	95.800	40.960	571.697	1.638	40.960	9.509
294.735	95.900	40.960	571.969	1.638	40.960	9.520
294.868	96.000	40.960	572.226	1.638	40.960	9.529
294.995	96.100	40.960	572.473	1.638	40.960	9.540
295.104	96.200	40.960	572.684	1.638	40.960	9.549
295.195	96.300	40.960	572.861	1.638	40.960	9.558
295.340	96.400	40.960	573.143	1.638	40.960	9.569
295.480	96.500	40.960	573.414	1.638	40.960	9.579
295.615	96.600	40.960	573.676	1.638	40.960	9.590
295.704	96.700	40.960	573.849	1.638	40.960	9.599
295.815	96.800	40.960	574.065	1.638	40.960	9.609
295.920	96.900	40.960	574.268	1.638	40.960	9.619
296.035	97.000	40.960	574.491	1.638	40.960	9.629
296.118	97.100	40.960	574.652	1.638	40.960	9.639
296.255	97.200	40.960	574.918	1.638	40.960	9.649
296.355	97.300	40.960	575.112	1.638	40.960	9.659
296.460	97.400	40.960	575.316	1.638	40.960	9.669
296.568	97.500	40.960	575.525	1.638	40.960	9.679
296.635	97.600	40.960	575.656	1.638	40.960	9.690
296.715	97.700	40.960	575.811	1.638	40.960	9.699
296.795	97.800	40.960	575.966	1.638	40.960	9.709
296.835	97.900	40.960	576.044	1.638	40.960	9.719
296.855	98.000	40.960	576.083	1.638	40.960	9.729
296.814	98.100	40.960	576.003	1.638	40.960	9.740
8.004	98.200	40.956	15.532	1.638	40.956	9.750
0.540	98.300	40.960	1.048	1.638	40.960	9.759
0.405	98.400	40.960	0.786	1.638	40.960	9.770
0.387	98.500	40.960	0.752	1.638	40.960	9.780
0.440	98.600	40.960	0.854	1.638	40.960	9.791
0.400	98.700	40.960	0.776	1.638	40.960	9.800
0.344	98.800	40.960	0.667	1.638	40.960	9.810
0.345	98.900	40.960	0.670	1.638	40.960	9.821
0.320	99.000	40.960	0.621	1.638	40.960	9.830
0.360	99.100	40.960	0.699	1.638	40.960	9.841
0.340	99.200	40.960	0.660	1.638	40.960	9.850
0.340	99.300	40.960	0.660	1.638	40.960	9.860
0.360	99.400	40.960	0.699	1.638	40.960	9.871
0.360	99.500	40.960	0.699	1.638	40.960	9.880
0.340	99.600	40.960	0.660	1.638	40.960	9.890
0.340	99.700	40.960	0.660	1.638	40.960	9.900
0.340	99.800	40.960	0.660	1.638	40.960	9.910
0.340	99.900	40.960	0.660	1.638	40.960	9.920
0.360	100.000	40.960	0.699	1.638	40.960	9.930
0.340	100.100	40.960	0.660	1.638	40.960	9.941
0.340	100.200	40.960	0.660	1.638	40.960	9.950
0.340	100.300	40.960	0.660	1.638	40.960	9.960
0.340	100.400	40.960	0.660	1.638	40.960	9.970
0.340	100.500	40.960	0.660	1.638	40.960	9.980
0.341	100.600	40.960	0.662	1.638	40.960	9.991
0.340	100.700	40.960	0.660	1.638	40.960	10.000
0.324	100.800	40.960	0.628	1.638	40.960	10.010
0.322	100.820	40.960	0.626	1.638	40.960	10.011